---
title: How do you handle exceptions in Flutter, and what strategies have you used?
---

Exceptions are errors that occur at runtime and can be handled in Flutter using `try-catch` blocks. Here's a simple example of how to handle exceptions in Flutter:

```dart
try {
  // Code that might throw an exception
} on Exception catch (e) {
  // Code that is executed when an exception is caught
  print("Caught exception: $e");
}
```

In this example, the code inside the try block is executed. If an exception is thrown, it is caught by the catch block, and the code inside the catch block is executed. You can access the details of the exception by using the e variable.

There are different strategies for handling exceptions in Flutter, including:

**Logging**: We can log the details of the exception to help with debugging and troubleshooting. We can use the print function or a logging library like logging or flutter_logging.

**Showing an error message**: We can show an error message to the user to let them know that something went wrong. For example, we might show a SnackBar with a message, or navigate to an error page.

**Retrying the operation**: If the exception was caused by a temporary error, we might want to retry the operation. For example, we might retry a network request if the first attempt failed due to a timeout.

**Handling specific exceptions**: We can handle specific exceptions by using multiple catch blocks. This allows us to handle each exception differently based on its type. For example, we might handle a SocketException differently from a `FormatException`.

Here's an example of a more advanced exception handling strategy:

```dart
try {
  // Code that might throw an exception
} on SocketException catch (e) {
  // Code that is executed when a SocketException is caught
  print("Caught SocketException: $e");
  // Retry the operation
} on FormatException catch (e) {
  // Code that is executed when a FormatException is caught
  print("Caught FormatException: $e");
  // Show an error message to the user
} catch (e) {
  // Code that is executed when any other exception is caught
  print("Caught exception: $e");
  // Log the exception for debugging purposes
}
```
